{"uuid": "77888721-74d9-4578-80b7-8b2b07fc2094", "children": ["87acf1c9-c4a8-491c-97dc-41c3a4d11732"], "befores": [{"name": "start_app", "status": "broken", "statusDetails": {"message": "selenium.common.exceptions.WebDriverException: Message: An unknown server-side error occurred while processing the command. Original error: Could not find a connected Android device.\n\n", "trace": "  File \"D:\\python\\lib\\site-packages\\pluggy\\callers.py\", line 187, in _multicall\n    res = hook_impl.function(*args)\n  File \"D:\\python\\lib\\site-packages\\_pytest\\fixtures.py\", line 918, in pytest_fixture_setup\n    result = call_fixture_func(fixturefunc, request, kwargs)\n  File \"D:\\python\\lib\\site-packages\\_pytest\\fixtures.py\", line 774, in call_fixture_func\n    res = next(it)\n  File \"D:\\app_auto_test\\testcases\\conftest.py\", line 18, in start_app\n    driver=base_driver()\n  File \"D:\\app_auto_test\\testcases\\conftest.py\", line 57, in base_driver\n    driver=webdriver.Remote('http://127.0.0.1:4723/wd/hub',caps)\n  File \"D:\\python\\lib\\site-packages\\appium\\webdriver\\webdriver.py\", line 144, in __init__\n    proxy\n  File \"D:\\python\\lib\\site-packages\\selenium\\webdriver\\remote\\webdriver.py\", line 157, in __init__\n    self.start_session(capabilities, browser_profile)\n  File \"D:\\python\\lib\\site-packages\\appium\\webdriver\\webdriver.py\", line 219, in start_session\n    response = self.execute(RemoteCommand.NEW_SESSION, parameters)\n  File \"D:\\python\\lib\\site-packages\\selenium\\webdriver\\remote\\webdriver.py\", line 321, in execute\n    self.error_handler.check_response(response)\n  File \"D:\\python\\lib\\site-packages\\selenium\\webdriver\\remote\\errorhandler.py\", line 242, in check_response\n    raise exception_class(message, screen, stacktrace)\n"}, "start": 1569546431666, "stop": 1569546462887}], "start": 1569546431666, "stop": 1569546462940}