{"uuid": "f402e41f-f795-4cb8-b057-5bda0d837839", "children": ["0876c966-17e6-459c-9527-b94dd3d4d9cd"], "befores": [{"name": "start_app", "status": "broken", "statusDetails": {"message": "selenium.common.exceptions.WebDriverException: Message: An unknown server-side error occurred while processing the command. Original error: Could not find a connected Android device.\n\n", "trace": "  File \"D:\\python\\lib\\site-packages\\pluggy\\callers.py\", line 187, in _multicall\n    res = hook_impl.function(*args)\n  File \"D:\\python\\lib\\site-packages\\_pytest\\fixtures.py\", line 918, in pytest_fixture_setup\n    result = call_fixture_func(fixturefunc, request, kwargs)\n  File \"D:\\python\\lib\\site-packages\\_pytest\\fixtures.py\", line 774, in call_fixture_func\n    res = next(it)\n  File \"D:\\app_auto_test\\testcases\\conftest.py\", line 18, in start_app\n    driver=base_driver()\n  File \"D:\\app_auto_test\\testcases\\conftest.py\", line 57, in base_driver\n    driver=webdriver.Remote('http://127.0.0.1:4723/wd/hub',caps)\n  File \"D:\\python\\lib\\site-packages\\appium\\webdriver\\webdriver.py\", line 144, in __init__\n    proxy\n  File \"D:\\python\\lib\\site-packages\\selenium\\webdriver\\remote\\webdriver.py\", line 157, in __init__\n    self.start_session(capabilities, browser_profile)\n  File \"D:\\python\\lib\\site-packages\\appium\\webdriver\\webdriver.py\", line 219, in start_session\n    response = self.execute(RemoteCommand.NEW_SESSION, parameters)\n  File \"D:\\python\\lib\\site-packages\\selenium\\webdriver\\remote\\webdriver.py\", line 321, in execute\n    self.error_handler.check_response(response)\n  File \"D:\\python\\lib\\site-packages\\selenium\\webdriver\\remote\\errorhandler.py\", line 242, in check_response\n    raise exception_class(message, screen, stacktrace)\n"}, "start": 1569546616020, "stop": 1569546643669}], "start": 1569546616020, "stop": 1569546643759}